<?xml version="1.0" encoding="utf-8"?>
<!-- This URDF was automatically created by SolidWorks to URDF Exporter! Originally created by Stephen Brawner (brawner@gmail.com) 
     Commit Version: 1.6.0-4-g7f85cfe  Build Version: 1.6.7995.38578
     For more information, please see http://wiki.ros.org/sw_urdf_exporter -->
<robot
  name="AZARM.SLDASM">
  <link
    name="base_link">
    <inertial>
      <origin
        xyz="-3.65505828007597E-18 -1.25967581376372E-18 0.0233708721378837"
        rpy="0 0 0" />
      <mass
        value="0.105065840403053" />
      <inertia
        ixx="5.78768576454175E-05"
        ixy="-2.67282735431197E-20"
        ixz="1.42368832626603E-20"
        iyy="7.15606076454175E-05"
        iyz="-7.07184791932616E-21"
        izz="4.24127212818137E-05" />
    </inertial>
    <visual>
      <origin
        xyz="0 0 0"
        rpy="0 0 0" />
      <geometry>
        <mesh
          filename="package://AZARM.SLDASM/meshes/base_link.STL" />
      </geometry>
      <material
        name="">
        <color
          rgba="0.792156862745098 0.819607843137255 0.933333333333333 1" />
      </material>
    </visual>
    <collision>
      <origin
        xyz="0 0 0"
        rpy="0 0 0" />
      <geometry>
        <mesh
          filename="package://AZARM.SLDASM/meshes/base_link.STL" />
      </geometry>
    </collision>
  </link>
  <link
    name="tilt_link">
    <inertial>
      <origin
        xyz="-1.2611827149659E-09 0.000729333408527516 -1.67068859472699E-08"
        rpy="0 0 0" />
      <mass
        value="5.81511393174933E-05" />
      <inertia
        ixx="2.15507056704182E-10"
        ixy="-1.50796515624021E-17"
        ixz="-1.4809915873036E-16"
        iyy="2.92251447670839E-10"
        iyz="-5.60339409363763E-16"
        izz="1.68436213445765E-10" />
    </inertial>
    <visual>
      <origin
        xyz="0 0 0"
        rpy="0 0 0" />
      <geometry>
        <mesh
          filename="package://AZARM.SLDASM/meshes/tilt_link.STL" />
      </geometry>
      <material
        name="">
        <color
          rgba="0.792156862745098 0.819607843137255 0.933333333333333 1" />
      </material>
    </visual>
    <collision>
      <origin
        xyz="0 0 0"
        rpy="0 0 0" />
      <geometry>
        <mesh
          filename="package://AZARM.SLDASM/meshes/tilt_link.STL" />
      </geometry>
    </collision>
  </link>
  <joint
    name="tilt_joint"
    type="revolute">
    <origin
      xyz="0 0 0.17"
      rpy="-1.5708 0 1.5708" />
    <parent
      link="base_link" />
    <child
      link="tilt_link" />
    <axis
      xyz="0 0 1" />
    <limit
      lower="-0.9"
      upper="0.9"
      effort="100"
      velocity="100" />
  </joint>
  <link
    name="palm_link">
    <inertial>
      <origin
        xyz="0.000139326328077952 -0.00434025244347531 0.0576803757518283"
        rpy="0 0 0" />
      <mass
        value="0.0756090808311836" />
      <inertia
        ixx="0.000157928803823983"
        ixy="7.04083460069003E-08"
        ixz="-1.47049681090686E-06"
        iyy="0.000112186068848503"
        iyz="4.46776822924556E-06"
        izz="4.91298231449849E-05" />
    </inertial>
    <visual>
      <origin
        xyz="0 0 0"
        rpy="0 0 0" />
      <geometry>
        <mesh
          filename="package://AZARM.SLDASM/meshes/palm_link.STL" />
      </geometry>
      <material
        name="">
        <color
          rgba="0.647058823529412 0.619607843137255 0.6 1" />
      </material>
    </visual>
    <collision>
      <origin
        xyz="0 0 0"
        rpy="0 0 0" />
      <geometry>
        <mesh
          filename="package://AZARM.SLDASM/meshes/palm_link.STL" />
      </geometry>
    </collision>
  </link>
  <joint
    name="palm_joint"
    type="revolute">
    <origin
      xyz="0 0.002 0"
      rpy="1.5708 0 0" />
    <parent
      link="tilt_link" />
    <child
      link="palm_link" />
    <axis
      xyz="0 0 1" />
    <limit
      lower="-3.14159"
      upper="0"
      effort="100"
      velocity="100" />
  </joint>
  <link
    name="pinky_link">
    <inertial>
      <origin
        xyz="0.0017820549626689 -0.000613293176593584 0.0163336690443128"
        rpy="0 0 0" />
      <mass
        value="0.00284841498918293" />
      <inertia
        ixx="2.89069230553783E-07"
        ixy="2.3095315046196E-09"
        ixz="-1.78553709803134E-08"
        iyy="2.99964229192158E-07"
        iyz="2.91987211416313E-08"
        izz="1.49822130412642E-07" />
    </inertial>
    <visual>
      <origin
        xyz="0 0 0"
        rpy="0 0 0" />
      <geometry>
        <mesh
          filename="package://AZARM.SLDASM/meshes/pinky_link.STL" />
      </geometry>
      <material
        name="">
        <color
          rgba="0.647058823529412 0.619607843137255 0.6 1" />
      </material>
    </visual>
    <collision>
      <origin
        xyz="0 0 0"
        rpy="0 0 0" />
      <geometry>
        <mesh
          filename="package://AZARM.SLDASM/meshes/pinky_link.STL" />
      </geometry>
    </collision>
  </link>
  <joint
    name="pinky_joint"
    type="revolute">
    <origin
      xyz="0.00053238 -0.04071 0.11076"
      rpy="0 0 -1.5708" />
    <parent
      link="palm_link" />
    <child
      link="pinky_link" />
    <axis
      xyz="1 0 0" />
    <limit
      lower="-1.5708"
      upper="0"
      effort="100"
      velocity="100" />
  </joint>
  <link
    name="pinky_mimic_link">
    <inertial>
      <origin
        xyz="0.00110870368695977 0.0045741664628078 0.014620949580515"
        rpy="0 0 0" />
      <mass
        value="0.00562690946535167" />
      <inertia
        ixx="7.1015499908551E-07"
        ixy="-9.17470173546304E-09"
        ixz="-3.71039587593776E-08"
        iyy="6.30896230770737E-07"
        iyz="-1.56604745729017E-07"
        izz="2.3029578674309E-07" />
    </inertial>
    <visual>
      <origin
        xyz="0 0 0"
        rpy="0 0 0" />
      <geometry>
        <mesh
          filename="package://AZARM.SLDASM/meshes/pinky_mimic_link.STL" />
      </geometry>
      <material
        name="">
        <color
          rgba="0.647058823529412 0.619607843137255 0.6 1" />
      </material>
    </visual>
    <collision>
      <origin
        xyz="0 0 0"
        rpy="0 0 0" />
      <geometry>
        <mesh
          filename="package://AZARM.SLDASM/meshes/pinky_mimic_link.STL" />
      </geometry>
    </collision>
  </link>
  <joint
    name="pinky_mimic_joint"
    type="revolute">
    <origin
      xyz="0.0034275 0.00025066 0.032821"
      rpy="0 0 0" />
    <parent
      link="pinky_link" />
    <child
      link="pinky_mimic_link" />
    <axis
      xyz="1 0 0" />
    <limit
      lower="-3.14159"
      upper="3.14159"
      effort="100"
      velocity="100" />
    <mimic
      joint="pinky_joint"
      multiplier="1"
      offset="0" />
  </joint>
  <link
    name="ring_link">
    <inertial>
      <origin
        xyz="0.00142294173005141 -0.00129072154615238 0.0203579955343289"
        rpy="0 0 0" />
      <mass
        value="0.00382261211395925" />
      <inertia
        ixx="5.52021987011609E-07"
        ixy="5.14714557280243E-09"
        ixz="-2.55389597661836E-08"
        iyy="5.69468033035357E-07"
        iyz="7.35455548546191E-08"
        izz="1.87705913426683E-07" />
    </inertial>
    <visual>
      <origin
        xyz="0 0 0"
        rpy="0 0 0" />
      <geometry>
        <mesh
          filename="package://AZARM.SLDASM/meshes/ring_link.STL" />
      </geometry>
      <material
        name="">
        <color
          rgba="0.647058823529412 0.619607843137255 0.6 1" />
      </material>
    </visual>
    <collision>
      <origin
        xyz="0 0 0"
        rpy="0 0 0" />
      <geometry>
        <mesh
          filename="package://AZARM.SLDASM/meshes/ring_link.STL" />
      </geometry>
    </collision>
  </link>
  <joint
    name="ring_joint"
    type="revolute">
    <origin
      xyz="0.00016823 -0.01558 0.11786"
      rpy="0 0 -1.5708" />
    <parent
      link="palm_link" />
    <child
      link="ring_link" />
    <axis
      xyz="1 0 0" />
    <limit
      lower="-1.48353"
      upper="0"
      effort="100"
      velocity="100" />
  </joint>
  <link
    name="ring_mimic_link">
    <inertial>
      <origin
        xyz="0.00114593140082822 0.00971703595716849 0.0156976573424628"
        rpy="0 0 0" />
      <mass
        value="0.00635546532886249" />
      <inertia
        ixx="9.81246420400804E-07"
        ixy="-2.51179161517114E-08"
        ixz="-3.63935787151237E-08"
        iyy="6.86069712230539E-07"
        iyz="-3.59092616871999E-07"
        izz="4.65691997283679E-07" />
    </inertial>
    <visual>
      <origin
        xyz="0 0 0"
        rpy="0 0 0" />
      <geometry>
        <mesh
          filename="package://AZARM.SLDASM/meshes/ring_mimic_link.STL" />
      </geometry>
      <material
        name="">
        <color
          rgba="0.647058823529412 0.619607843137255 0.6 1" />
      </material>
    </visual>
    <collision>
      <origin
        xyz="0 0 0"
        rpy="0 0 0" />
      <geometry>
        <mesh
          filename="package://AZARM.SLDASM/meshes/ring_mimic_link.STL" />
      </geometry>
    </collision>
  </link>
  <joint
    name="ring_mimic_joint"
    type="revolute">
    <origin
      xyz="0.00286 0 0.0409"
      rpy="0 0 0" />
    <parent
      link="ring_link" />
    <child
      link="ring_mimic_link" />
    <axis
      xyz="1 0 0" />
    <limit
      lower="-3.14159"
      upper="3.14159"
      effort="100"
      velocity="100" />
    <mimic
      joint="ring_joint"
      multiplier="1"
      offset="0" />
  </joint>
  <link
    name="middle_link">
    <inertial>
      <origin
        xyz="0.000405615187407336 -0.00143109938804946 0.0232048672034128"
        rpy="0 0 0" />
      <mass
        value="0.00435101489045583" />
      <inertia
        ixx="7.37234099995634E-07"
        ixy="1.59808191484657E-09"
        ixz="-9.37016835548716E-09"
        iyy="7.60393827066509E-07"
        iyz="9.11626916011677E-08"
        izz="2.06162513534503E-07" />
    </inertial>
    <visual>
      <origin
        xyz="0 0 0"
        rpy="0 0 0" />
      <geometry>
        <mesh
          filename="package://AZARM.SLDASM/meshes/middle_link.STL" />
      </geometry>
      <material
        name="">
        <color
          rgba="0.647058823529412 0.619607843137255 0.6 1" />
      </material>
    </visual>
    <collision>
      <origin
        xyz="0 0 0"
        rpy="0 0 0" />
      <geometry>
        <mesh
          filename="package://AZARM.SLDASM/meshes/middle_link.STL" />
      </geometry>
    </collision>
  </link>
  <joint
    name="middle_joint"
    type="revolute">
    <origin
      xyz="0.00016823 0.0072093 0.11765"
      rpy="0 0 -1.5708" />
    <parent
      link="palm_link" />
    <child
      link="middle_link" />
    <axis
      xyz="1 0 0" />
    <limit
      lower="-1.48353"
      upper="0"
      effort="100"
      velocity="100" />
  </joint>
  <link
    name="middle_mimic_link">
    <inertial>
      <origin
        xyz="0.000345295830106925 0.0127273363551072 0.0170120766603321"
        rpy="0 0 0" />
      <mass
        value="0.00710270866127903" />
      <inertia
        ixx="1.29588990900115E-06"
        ixy="-9.12339135111873E-09"
        ixz="-1.0789157628165E-08"
        iyy="7.97173801636548E-07"
        iyz="-5.20228611199526E-07"
        izz="6.8815050024616E-07" />
    </inertial>
    <visual>
      <origin
        xyz="0 0 0"
        rpy="0 0 0" />
      <geometry>
        <mesh
          filename="package://AZARM.SLDASM/meshes/middle_mimic_link.STL" />
      </geometry>
      <material
        name="">
        <color
          rgba="0.647058823529412 0.619607843137255 0.6 1" />
      </material>
    </visual>
    <collision>
      <origin
        xyz="0 0 0"
        rpy="0 0 0" />
      <geometry>
        <mesh
          filename="package://AZARM.SLDASM/meshes/middle_mimic_link.STL" />
      </geometry>
    </collision>
  </link>
  <joint
    name="middle_mimic_joint"
    type="revolute">
    <origin
      xyz="0.00080281 0 0.045993"
      rpy="0 0 0" />
    <parent
      link="middle_link" />
    <child
      link="middle_mimic_link" />
    <axis
      xyz="1 0 0" />
    <limit
      lower="-3.14159"
      upper="3.14159"
      effort="100"
      velocity="100" />
    <mimic
      joint="middle_joint"
      multiplier="1"
      offset="0" />
  </joint>
  <link
    name="pointer_link">
    <inertial>
      <origin
        xyz="-4.46665278444613E-08 -0.00145978404501389 0.0231866899386782"
        rpy="0 0 0" />
      <mass
        value="0.00430054577129327" />
      <inertia
        ixx="7.2680915639404E-07"
        ixy="-5.76457316669875E-12"
        ixz="-3.33068283083741E-12"
        iyy="7.51246448794749E-07"
        iyz="8.87861916234815E-08"
        izz="2.02703110164289E-07" />
    </inertial>
    <visual>
      <origin
        xyz="0 0 0"
        rpy="0 0 0" />
      <geometry>
        <mesh
          filename="package://AZARM.SLDASM/meshes/pointer_link.STL" />
      </geometry>
      <material
        name="">
        <color
          rgba="0.647058823529412 0.619607843137255 0.6 1" />
      </material>
    </visual>
    <collision>
      <origin
        xyz="0 0 0"
        rpy="0 0 0" />
      <geometry>
        <mesh
          filename="package://AZARM.SLDASM/meshes/pointer_link.STL" />
      </geometry>
    </collision>
  </link>
  <joint
    name="pointer_joint"
    type="revolute">
    <origin
      xyz="0.00016729 0.028465 0.1131"
      rpy="0 0 -1.5708" />
    <parent
      link="palm_link" />
    <child
      link="pointer_link" />
    <axis
      xyz="1 0 0" />
    <limit
      lower="-1.5708"
      upper="0"
      effort="100"
      velocity="100" />
  </joint>
  <link
    name="pointer_mimic_link">
    <inertial>
      <origin
        xyz="4.83338837184502E-05 0.00948108730078251 0.0159732581009296"
        rpy="0 0 0" />
      <mass
        value="0.00632636073888504" />
      <inertia
        ixx="9.7425233673214E-07"
        ixy="-7.16546852490424E-12"
        ixz="-1.51928793829775E-10"
        iyy="6.89677632645156E-07"
        iyz="-3.53352679409196E-07"
        izz="4.49289688683112E-07" />
    </inertial>
    <visual>
      <origin
        xyz="0 0 0"
        rpy="0 0 0" />
      <geometry>
        <mesh
          filename="package://AZARM.SLDASM/meshes/pointer_mimic_link.STL" />
      </geometry>
      <material
        name="">
        <color
          rgba="0.647058823529412 0.619607843137255 0.6 1" />
      </material>
    </visual>
    <collision>
      <origin
        xyz="0 0 0"
        rpy="0 0 0" />
      <geometry>
        <mesh
          filename="package://AZARM.SLDASM/meshes/pointer_mimic_link.STL" />
      </geometry>
    </collision>
  </link>
  <joint
    name="pointer_mimic_joint"
    type="revolute">
    <origin
      xyz="0 0 0.046"
      rpy="0 0 0" />
    <parent
      link="pointer_link" />
    <child
      link="pointer_mimic_link" />
    <axis
      xyz="1 0 0" />
    <limit
      lower="-3.14159"
      upper="3.14159"
      effort="100"
      velocity="100" />
    <mimic
      joint="pointer_joint"
      multiplier="1"
      offset="0" />
  </joint>
  <link
    name="thumb_swivel_link">
    <inertial>
      <origin
        xyz="-0.0240609552040613 0.000537100639586875 0.00573428572634524"
        rpy="0 0 0" />
      <mass
        value="0.00807597668556131" />
      <inertia
        ixx="1.08043710320532E-06"
        ixy="1.68624171131996E-07"
        ixz="1.08772170504102E-06"
        iyy="3.03147252079577E-06"
        iyz="-1.34639716373518E-07"
        izz="2.48856447081333E-06" />
    </inertial>
    <visual>
      <origin
        xyz="0 0 0"
        rpy="0 0 0" />
      <geometry>
        <mesh
          filename="package://AZARM.SLDASM/meshes/thumb_swivel_link.STL" />
      </geometry>
      <material
        name="">
        <color
          rgba="0.792156862745098 0.819607843137255 0.933333333333333 1" />
      </material>
    </visual>
    <collision>
      <origin
        xyz="0 0 0"
        rpy="0 0 0" />
      <geometry>
        <mesh
          filename="package://AZARM.SLDASM/meshes/thumb_swivel_link.STL" />
      </geometry>
    </collision>
  </link>
  <joint
    name="thumb_swivel_joint"
    type="revolute">
    <origin
      xyz="0.0022482 0.0086241 0.036295"
      rpy="0 0 -1.5708" />
    <parent
      link="palm_link" />
    <child
      link="thumb_swivel_link" />
    <axis
      xyz="0 0 1" />
    <limit
      lower="-1.39626"
      upper="0"
      effort="100"
      velocity="100" />
  </joint>
  <link
    name="thumb_link">
    <inertial>
      <origin
        xyz="0.0256273062999669 -0.00431444759252197 4.34271946556097E-07"
        rpy="0 0 0" />
      <mass
        value="0.00621086322047085" />
      <inertia
        ixx="3.16321132822082E-07"
        ixy="-1.30190476637141E-07"
        ixz="1.5871208101121E-11"
        iyy="2.36922111980103E-06"
        iyz="-8.24575343924549E-12"
        izz="2.3409472550813E-06" />
    </inertial>
    <visual>
      <origin
        xyz="0 0 0"
        rpy="0 0 0" />
      <geometry>
        <mesh
          filename="package://AZARM.SLDASM/meshes/thumb_link.STL" />
      </geometry>
      <material
        name="">
        <color
          rgba="0.647058823529412 0.619607843137255 0.6 1" />
      </material>
    </visual>
    <collision>
      <origin
        xyz="0 0 0"
        rpy="0 0 0" />
      <geometry>
        <mesh
          filename="package://AZARM.SLDASM/meshes/thumb_link.STL" />
      </geometry>
    </collision>
  </link>
  <joint
    name="thumb_joint"
    type="revolute">
    <origin
      xyz="-0.052668 0.0037572 0.02242"
      rpy="1.7695 -0.48108 3.0361" />
    <parent
      link="thumb_swivel_link" />
    <child
      link="thumb_link" />
    <axis
      xyz="0 0 1" />
    <limit
      lower="0"
      upper="1.5708"
      effort="100"
      velocity="100" />
  </joint>
  <link
    name="thumb_mimic_link">
    <inertial>
      <origin
        xyz="-0.00895195042877733 -0.00630026557634536 -0.000131518813433762"
        rpy="0 0 0" />
      <mass
        value="0.00432808679098043" />
      <inertia
        ixx="1.19629651940253E-07"
        ixy="-1.00661494389658E-08"
        ixz="-3.96031076876252E-09"
        iyy="4.16050123472744E-07"
        iyz="-8.4255291563161E-11"
        izz="4.31485445385843E-07" />
    </inertial>
    <visual>
      <origin
        xyz="0 0 0"
        rpy="0 0 0" />
      <geometry>
        <mesh
          filename="package://AZARM.SLDASM/meshes/thumb_mimic_link.STL" />
      </geometry>
      <material
        name="">
        <color
          rgba="0.647058823529412 0.619607843137255 0.6 1" />
      </material>
    </visual>
    <collision>
      <origin
        xyz="0 0 0"
        rpy="0 0 0" />
      <geometry>
        <mesh
          filename="package://AZARM.SLDASM/meshes/thumb_mimic_link.STL" />
      </geometry>
    </collision>
  </link>
  <joint
    name="thumb_mimic_joint"
    type="revolute">
    <origin
      xyz="0.057532 0.0040526 0"
      rpy="-3.1416 -0.01399 3.1416" />
    <parent
      link="thumb_link" />
    <child
      link="thumb_mimic_link" />
    <axis
      xyz="0 0 1" />
    <limit
      lower="-3.14159"
      upper="3.14159"
      effort="100"
      velocity="100" />
    <mimic
      joint="thumb_joint"
      multiplier="-1"
      offset="0" />
  </joint>
</robot>